Workbook

Sheet Lisez-moi
A1: PREVISIONNEL FINANCIER — Mycelium
A2: Operateur de la conformite EGalim en restauration collective
A3: Revision du 15 aout 2026 — modele a 5 lignes de revenu, exercice de septembre a aout
A5: CE QUI A CHANGE PAR RAPPORT A LA VERSION DE JUILLET
A6: Avant | B6: Une seule ligne de revenu : abonnement 600 €/mois par cantine, des le mois 4.
A7: Maintenant | B7: Cinq lignes : diagnostic one-shot, declaration assistee, abonnement Conformite, abonnement Operateur, commission d'apport.
A8: Pourquoi | B8: Un 'oui' a 690 € se decroche. Un 'oui' a 600 €/mois se merite. On entre par le diagnostic, qui ne fait courir aucun risque.
A9: Calendrier | B9: L'exercice va de SEPTEMBRE a AOUT. Le secteur est saisonnier : aout est mort, janvier-mars est le pic (teledeclaration).
A10: Logistique | B10: Sortie du cas de base. C'est l'etage 5, sous conditions, pas avant l'annee 3. Voir doc 08.
A12: COMMENT UTILISER CE CLASSEUR
A13: Cellules jaunes | B13: Les seules a modifier. Tout le reste se recalcule automatiquement.
A14: Onglet Hypotheses | B14: Tous les leviers : prix des 5 lignes de revenu, montee en charge, couts, cotisations, scenarios.
A15: Onglet Previsionnel_A1 | B15: Annee 1 mois par mois (sept. 2026 -> aout 2027). Ajuster les 4 lignes bleues de volume.
A16: Onglet PL_3ans | B16: Compte de resultat sur 3 ans, pilote par les hypotheses.
A17: Onglet Scenarios | B17: Comparaison prudent / base / ambitieux.
A18: Onglet Unit_economics | B18: Valeur par client selon l'etage, et regle de sortie de l'emploi.
A19: Onglet Simulateur_ratio | B19: OUTIL DE VENTE : simule le gain de points EGalim par famille de produits, chez un prospect.
A21: LES DEUX INDICATEURS QUI DECIDENT DE TOUT
A22: Taux de conversion diagnostic -> abonnement | B22: A 45 % le modele est sain. A 20 % on vend des rapports au lieu de construire une entreprise.
A23: Pente du MRR (revenu recurrent) | B23: Un CA annuel porte par du one-shot est un echec deguise. La ligne 'abonnes' est le vrai signal.
A25: SOURCES DES CHIFFRES DE MARCHE
A26: • Repas et CA secteur : Food Service Vision 2024.
A27: • Conformite EGalim (15 % / 30 % / 21 %) : campagne ma cantine 2024 (donnees 2023).
A28: • Part de bio : Agence Bio 2024.
A29: • Prix, ramp et couts : hypotheses fondateur, a affiner avec les premiers deals.
A31: AVERTISSEMENT : toute projection de startup est incertaine. Ce modele sert a cadrer et a jouer des scenarios, pas a predire. Les points juridiques et fiscaux marques [A CONFIRMER] dans le doc 06 doivent l'etre avec un professionnel AVANT le contrat concerne.

Sheet Hypotheses
A1: HYPOTHESES — leviers modifiables
A2: Modifiez uniquement les cellules jaunes. Tout se recalcule.
A4: REVENU — PRIX UNITAIRES (annee 1)
A5: Diagnostic EGalim — prix moyen (€) | B5: 950 | C5: S 690 / M 1 190 / L 1 900
A6: Declaration assistee — prix moyen (€) | B6: 450 | C6: Fenetre janvier -> 31 mars
A7: Abonnement Conformite — prix moyen (€/mois) | B7: 290 | C7: S 190 / M 290 / L 390
A8: Abonnement Operateur — prix moyen (€/mois) | B8: 650 | C8: S 450 / M 650 / L 900 — inclut le Conformite
A9: Flux denrees intermedie par client Operateur (€/mois) | B9: 2500 | C9: Ne passe JAMAIS par nos livres
A10: Taux de commission d'apport (%) | B10: 0.06 | C10: Payee par le producteur, pas par la cantine
A12: INDEXATION DES PRIX
A13: Indexation annee 2 (x) | B13: 1.03 | C13: Appliquee a tous les prix
A14: Indexation annee 3 (x) | B14: 1.06
A16: MONTEE EN CHARGE — ANNEE 2 (sept. 2027 -> aout 2028)
A17: Diagnostics vendus | B17: 35
A18: Declarations vendues | B18: 20
A19: Abonnes Conformite — moyenne sur l'annee | B19: 16 | C19: Moteur du CA d'abonnement
A20: Abonnes Conformite — fin d'annee | B20: 24 | C20: Indicatif
A21: Abonnes Operateur — moyenne sur l'annee | B21: 9
A22: Abonnes Operateur — fin d'annee | B22: 14 | C22: Indicatif
A23: Flux denrees par Operateur (€/mois) | B23: 3000
A25: MONTEE EN CHARGE — ANNEE 3 (sept. 2028 -> aout 2029)
A26: Diagnostics vendus | B26: 70
A27: Declarations vendues | B27: 45
A28: Abonnes Conformite — moyenne sur l'annee | B28: 42
A29: Abonnes Conformite — fin d'annee | B29: 60 | C29: Indicatif
A30: Abonnes Operateur — moyenne sur l'annee | B30: 27
A31: Abonnes Operateur — fin d'annee | B31: 40 | C31: Indicatif
A32: Flux denrees par Operateur (€/mois) | B32: 3200
A33: Cantines livrees via 3PL (etage 5) | B33: 12 | C33: Sous conditions — voir doc 08
A34: Marge orchestration logistique (€/cantine/mois) | B34: 60 | C34: Debloqueur, pas centre de profit
A36: COUTS — ANNEE 1 (micro-entreprise)
A37: Deplacements (€/an) | B37: 1200
A38: Compta & juridique (€/an) | B38: 1400 | C38: Consultations expert-comptable + avocat
A39: Assurance RC pro (€/an) | B39: 480 | C39: DOIT couvrir explicitement le conseil/audit
A40: Logiciel, hebergement, API Claude (€/an) | B40: 720 | C40: ~0,50 a 2 € d'API par diagnostic
A41: Marketing & impression (€/an) | B41: 600
A42: Divers & outils (€/an) | B42: 480
A43: Taux cotisations micro BNC (%) | B43: 0.212 | C43: A confirmer avec l'expert-comptable
A44: Reduction ACRE annee 1 (%) | B44: 0.5
A46: COUTS — ANNEE 2 (SASU)
...

Sheet Previsionnel_A1
A1: PREVISIONNEL ANNEE 1 — septembre 2026 -> aout 2027 (mensuel)
A2: Ajustez les 4 lignes jaunes de volume. Aout et septembre sans vente : les cantines sont fermees, c'est le plan.
A4: Poste / Mois | B4: sept. 26 | C4: oct. 26 | D4: nov. 26 | E4: dec. 26 | F4: janv. 27 | G4: fevr. 27 | H4: mars 27 | I4: avr. 27 | J4: mai 27 | K4: juin 27 | L4: juil. 27 | M4: aout 27 | N4: Total A1
A5: Diagnostics vendus dans le mois | B5: 0 | C5: 2 | D5: 1 | E5: 1 | F5: 2 | G5: 3 | H5: 3 | I5: 1 | J5: 1 | K5: 0 | L5: 0 | M5: 0 | N5: =SUM(B5:M5)
A6: Declarations assistees vendues | B6: 0 | C6: 0 | D6: 0 | E6: 0 | F6: 2 | G6: 3 | H6: 3 | I6: 0 | J6: 0 | K6: 0 | L6: 0 | M6: 0 | N6: =SUM(B6:M6)
A7: Abonnes Conformite (fin de mois) | B7: 0 | C7: 0 | D7: 0 | E7: 1 | F7: 1 | G7: 2 | H7: 3 | I7: 4 | J7: 5 | K7: 5 | L7: 6 | M7: 7 | N7: =M7
A8: Abonnes Operateur (fin de mois) | B8: 0 | C8: 0 | D8: 0 | E8: 0 | F8: 1 | G8: 1 | H8: 1 | I8: 1 | J8: 2 | K8: 2 | L8: 3 | M8: 3 | N8: =M8
A10: CA diagnostics (€) | B10: =B5*Hypotheses!$B$5 | C10: =C5*Hypotheses!$B$5 | D10: =D5*Hypotheses!$B$5 | E10: =E5*Hypotheses!$B$5 | F10: =F5*Hypotheses!$B$5 | G10: =G5*Hypotheses!$B$5 | H10: =H5*Hypotheses!$B$5 | I10: =I5*Hypotheses!$B$5 | ... M10: =M5*Hypotheses!$B$5 | N10: =SUM(B10:M10)
A11: CA declarations assistees (€) | B11: =B6*Hypotheses!$B$6 | C11: =C6*Hypotheses!$B$6 | D11: =D6*Hypotheses!$B$6 | E11: =E6*Hypotheses!$B$6 | F11: =F6*Hypotheses!$B$6 | G11: =G6*Hypotheses!$B$6 | H11: =H6*Hypotheses!$B$6 | I11: =I6*Hypotheses!$B$6 | ... M11: =M6*Hypotheses!$B$6 | N11: =SUM(B11:M11)
A12: CA abonnements Conformite (€) | B12: =B7*Hypotheses!$B$7 | C12: =C7*Hypotheses!$B$7 | D12: =D7*Hypotheses!$B$7 | E12: =E7*Hypotheses!$B$7 | F12: =F7*Hypotheses!$B$7 | G12: =G7*Hypotheses!$B$7 | H12: =H7*Hypotheses!$B$7 | I12: =I7*Hypotheses!$B$7 | ... M12: =M7*Hypotheses!$B$7 | N12: =SUM(B12:M12)
A13: CA abonnements Operateur (€) | B13: =B8*Hypotheses!$B$8 | C13: =C8*Hypotheses!$B$8 | D13: =D8*Hypotheses!$B$8 | E13: =E8*Hypotheses!$B$8 | F13: =F8*Hypotheses!$B$8 | G13: =G8*Hypotheses!$B$8 | H13: =H8*Hypotheses!$B$8 | I13: =I8*Hypotheses!$B$8 | ... M13: =M8*Hypotheses!$B$8 | N13: =SUM(B13:M13)
A14: CA commissions d'apport (€) | B14: =B8*Hypotheses!$B$9*Hypotheses!$B$10 | C14: =C8*Hypotheses!$B$9*Hypotheses!$B$10 | D14: =D8*Hypotheses!$B$9*Hypotheses!$B$10 | E14: =E8*Hypotheses!$B$9*Hypotheses!$B$10 | F14: =F8*Hypotheses!$B$9*Hypotheses!$B$10 | G14: =G8*Hypotheses!$B$9*Hypotheses!$B$10 | H14: =H8*Hypotheses!$B$9*Hypotheses!$B$10 | I14: =I8*Hypotheses!$B$9*Hypotheses!$B$10 | ... M14: =M8*Hypotheses!$B$9*Hypotheses!$B$10 | N14: =SUM(B14:M14)
A15: CA TOTAL (€) | B15: =SUM(B10:B14) | C15: =SUM(C10:C14) | D15: =SUM(D10:D14) | E15: =SUM(E10:E14) | F15: =SUM(F10:F14) | G15: =SUM(G10:G14) | H15: =SUM(H10:H14) | I15: =SUM(I10:I14) | ... M15: =SUM(M10:M14) | N15: =SUM(B15:M15)
A17: Couts fixes (€) | B17: =SUM(Hypotheses!$B$37:$B$42)/12 | C17: =SUM(Hypotheses!$B$37:$B$42)/12 | D17: =SUM(Hypotheses!$B$37:$B$42)/12 | E17: =SUM(Hypotheses!$B$37:$B$42)/12 | F17: =SUM(Hypotheses!$B$37:$B$42)/12 | G17: =SUM(Hypotheses!$B$37:$B$42)/12 | H17: =SUM(Hypotheses!$B$37:$B$42)/12 | I17: =SUM(Hypotheses!$B$37:$B$42)/12 | ... M17: =SUM(Hypotheses!$B$37:$B$42)/12 | N17: =SUM(B17:M17)
A18: Cotisations micro (€) | B18: =B15*Hypotheses!$B$43*(1-Hypotheses!$B$44) | C18: =C15*Hypotheses!$B$43*(1-Hypotheses!$B$44) | D18: =D15*Hypotheses!$B$43*(1-Hypotheses!$B$44) | E18: =E15*Hypotheses!$B$43*(1-Hypotheses!$B$44) | F18: =F15*Hypotheses!$B$43*(1-Hypotheses!$B$44) | G18: =G15*Hypotheses!$B$43*(1-Hypotheses!$B$44) | H18: =H15*Hypotheses!$B$43*(1-Hypotheses!$B$44) | I18: =I15*Hypotheses!$B$43*(1-Hypotheses!$B$44) | ... M18: =M15*Hypotheses!$B$43*(1-Hypotheses!$B$44) | N18: =SUM(B18:M18)
A19: Total charges (€) | B19: =B17+B18 | C19: =C17+C18 | D19: =D17+D18 | E19: =E17+E18 | F19: =F17+F18 | G19: =G17+G18 | H19: =H17+H18 | I19: =I17+I18 | ... M19: =M17+M18 | N19: =SUM(B19:M19)
A20: Resultat mensuel (€) | B20: =B15-B19 | C20: =C15-C19 | D20: =D15-D19 | E20: =E15-E19 | F20: =F15-F19 | G20: =G15-G19 | H20: =H15-H19 | I20: =I15-I19 | ... M20: =M15-M19 | N20: =SUM(B20:M20)
A21: Tresorerie cumulee (€) | B21: =B20 | C21: =B21+C20 | D21: =C21+D20 | E21: =D21+E20 | F21: =E21+F20 | G21: =F21+G20 | H21: =G21+H20 | I21: =H21+I20 | J21: =I21+J20 | ... M21: =L21+M20 | N21: =M21
A23: MRR en sortie (recurrent seul, aout 2027) | B23: =M12+M13+M14 | D23: C'est le vrai signal, pas le CA annuel. Voir Unit_economics.
A24: Part du one-shot dans le CA annuel | B24: =(N10+N11)/N15 | D24: Normal en A1 (finance le demarrage). Doit baisser en A2.

Sheet PL_3ans
A1: COMPTE DE RESULTAT — 3 ANS
A2: Cas de base, pilote par l'onglet Hypotheses. Exercices de septembre a aout.
A4: Poste | B4: Annee 1 | C4: Annee 2 | D4: Annee 3
A5: Diagnostics vendus | B5: =Previsionnel_A1!N5 | C5: =Hypotheses!$B$17 | D5: =Hypotheses!$B$26
A6: Abonnes Conformite (fin d'annee) | B6: =Previsionnel_A1!M7 | C6: =Hypotheses!$B$20 | D6: =Hypotheses!$B$29
A7: Abonnes Operateur (fin d'annee) | B7: =Previsionnel_A1!M8 | C7: =Hypotheses!$B$22 | D7: =Hypotheses!$B$31
A9: CA diagnostics | B9: =Previsionnel_A1!N10 | C9: =Hypotheses!$B$17*Hypotheses!$B$5*Hypotheses!$B$13 | D9: =Hypotheses!$B$26*Hypotheses!$B$5*Hypotheses!$B$14
A10: CA declarations assistees | B10: =Previsionnel_A1!N11 | C10: =Hypotheses!$B$18*Hypotheses!$B$6*Hypotheses!$B$13 | D10: =Hypotheses!$B$27*Hypotheses!$B$6*Hypotheses!$B$14
A11: CA abonnements Conformite | B11: =Previsionnel_A1!N12 | C11: =Hypotheses!$B$19*Hypotheses!$B$7*Hypotheses!$B$13*12 | D11: =Hypotheses!$B$28*Hypotheses!$B$7*Hypotheses!$B$14*12
A12: CA abonnements Operateur | B12: =Previsionnel_A1!N13 | C12: =Hypotheses!$B$21*Hypotheses!$B$8*Hypotheses!$B$13*12 | D12: =Hypotheses!$B$30*Hypotheses!$B$8*Hypotheses!$B$14*12
A13: CA commissions d'apport | B13: =Previsionnel_A1!N14 | C13: =Hypotheses!$B$21*Hypotheses!$B$23*Hypotheses!$B$10*12 | D13: =Hypotheses!$B$30*Hypotheses!$B$32*Hypotheses!$B$10*12
A14: CA orchestration logistique (etage 5) | B14: =0 | C14: =0 | D14: =Hypotheses!$B$33*Hypotheses!$B$34*12
A15: CHIFFRE D'AFFAIRES | B15: =SUM(B9:B14) | C15: =SUM(C9:C14) | D15: =SUM(D9:D14)
A17: CHARGES
A18: Remunerations chargees | B18: =0 | C18: =Hypotheses!$B$47 | D18: =Hypotheses!$B$55
A19: Infrastructure & logiciel | B19: =Hypotheses!$B$40 | C19: =Hypotheses!$B$48 | D19: =Hypotheses!$B$56
A20: Marketing & deplacements | B20: =Hypotheses!$B$37+Hypotheses!$B$41 | C20: =Hypotheses!$B$49 | D20: =Hypotheses!$B$57
A21: Compta, juridique, assurances | B21: =Hypotheses!$B$38+Hypotheses!$B$39 | C21: =Hypotheses!$B$50 | D21: =Hypotheses!$B$58
A22: Sous-traitance | B22: =0 | C22: =Hypotheses!$B$51 | D22: =Hypotheses!$B$59
A23: Locaux & divers | B23: =Hypotheses!$B$42 | C23: =Hypotheses!$B$52 | D23: =Hypotheses!$B$60
A24: Cotisations micro (avec ACRE) | B24: =Previsionnel_A1!N18 | C24: =0 | D24: =0
A25: TOTAL CHARGES | B25: =SUM(B18:B24) | C25: =SUM(C18:C24) | D25: =SUM(D18:D24)
A27: RESULTAT AVANT IMPOT | B27: =B15-B25 | C27: =C15-C25 | D27: =D15-D25
A28: Marge (%) | B28: =IF(B15=0,0,B27/B15) | C28: =IF(C15=0,0,C27/C15) | D28: =IF(D15=0,0,D27/D15)
A30: Annee 1 : structure micro, le resultat est le revenu du fondateur. Annee 2 : bascule SASU + 1 embauche. Annee 3 : equipe de 4-5, resultat reinvesti dans l'expansion, pas sorti.

Sheet Scenarios
A1: SCENARIOS
A2: Bornes indicatives : le facteur agit sur les volumes (diagnostics et abonnes).
B4: Prudent | C4: Base | D4: Ambitieux
A5: Facteur volumes | B5: =Hypotheses!$B$67 | C5: =Hypotheses!$B$68 | D5: =Hypotheses!$B$69
A6: Diagnostics annee 1 | B6: =Previsionnel_A1!$N$5*B5 | C6: =Previsionnel_A1!$N$5*C5 | D6: =Previsionnel_A1!$N$5*D5
A7: Abonnes Conformite fin A1 | B7: =Previsionnel_A1!$M$7*B5 | C7: =Previsionnel_A1!$M$7*C5 | D7: =Previsionnel_A1!$M$7*D5
A8: Abonnes Operateur fin A1 | B8: =Previsionnel_A1!$M$8*B5 | C8: =Previsionnel_A1!$M$8*C5 | D8: =Previsionnel_A1!$M$8*D5
A9: CA annee 1 | B9: =PL_3ans!$B$15*B5 | C9: =PL_3ans!$B$15*C5 | D9: =PL_3ans!$B$15*D5
A10: CA annee 3 | B10: =PL_3ans!$D$15*B5 | C10: =PL_3ans!$D$15*C5 | D10: =PL_3ans!$D$15*D5
A12: Le resultat ne se met pas a l'echelle lineairement (part de couts fixes). Ces bornes ne portent que sur le CA et les volumes.
A14: CE QUI FAIT BASCULER D'UN SCENARIO A L'AUTRE
A15: Prudent | B15: Cycle de vente plus long, conversion diagnostic -> abonnement sous 30 %.
A16: Base | B16: Le plan tel qu'ecrit : 45 % de conversion, 14 diagnostics en A1.
A17: Ambitieux | B17: Le simulateur en ligne ramene du volume entrant, et un reseau (creches ou EHPAD en groupe) ouvre 5 sites d'un coup.

Sheet Unit_economics
A1: ECONOMIE UNITAIRE & SEUIL DE SORTIE DE L'EMPLOI
A3: VALEUR CLIENT SELON L'ETAGE ATTEINT
A4: Situation du client | B4: Revenu / an | C4: Temps humain / an
A5: Diagnostic seul (one-shot) | B5: =Hypotheses!$B$5 | C5: ~8 h — marge tres elevee
A6: Diagnostic + abonnement Conformite | B6: =Hypotheses!$B$5+Hypotheses!$B$7*12 | C6: ~20 h — marge elevee, scalable
A7: Abonnement Operateur (Conformite inclus) + commission | B7: =Hypotheses!$B$8*12+Hypotheses!$B$9*Hypotheses!$B$10*12 | C7: ~60 h (1 h/semaine) — le poste qui limite la croissance
A9: LE PLAFOND DU FONDATEUR SEUL
A10: Temps de coordination par client Operateur (h/semaine) | B10: 1
A11: Heures disponibles par semaine | B11: 17
A12: Part du temps consacree a la coordination (%) | B12: 0.5
A13: PLAFOND : clients Operateur gerables par le fondateur seul | B13: =FLOOR(B11*B12/B10,1) | C13: C'est ce plafond, pas la demande, qui dicte le rythme d'embauche et la roadmap produit.
A15: SEUIL DE RENTABILITE PERSONNEL
A16: Revenu net mensuel vise | B16: =Hypotheses!$B$63
A17: CA mensuel necessaire (apres cotisations) | B17: =Hypotheses!$B$63/(1-Hypotheses!$B$43)
A18: Charges fixes mensuelles | B18: =SUM(Hypotheses!$B$37:$B$42)/12
A19: SEUIL : CA mensuel total necessaire | B19: =B17+B18
A21: REGLE DE SORTIE DE L'EMPLOI DE SERVEUR
A22: MRR minimum avant de quitter le job (seuil x facteur de securite) | B22: =B19*Hypotheses!$B$64
A23: MRR atteint en fin d'annee 1 (aout 2027) | B23: =Previsionnel_A1!B23
A24: Abonnes Conformite necessaires (si aucun Operateur) | B24: =CEILING(B22/Hypotheses!$B$7,1)
A25: Mix realiste : abonnes Conformite avec 3 Operateur | B25: =CEILING((B22-3*(Hypotheses!$B$8+Hypotheses!$B$9*Hypotheses!$B$10))/Hypotheses!$B$7,1)
A27: REGLE : le MRR SEUL (hors diagnostics) doit couvrir ce montant pendant 3 mois consecutifs. Le facteur de securite absorbe un churn, un mois creux et un impaye. Quitter un emploi au mois exact du point mort, c'est se remettre sous pression de tresorerie au pire moment — et la pression de tresorerie est ce qui fait accepter les mauvais clients et les mauvaises marges.

Sheet Simulateur_ratio
A1: SIMULATEUR DE RATIO EGALIM — outil de rendez-vous
A2: A remplir avec les chiffres du prospect. Montre en 2 minutes que 50/20 est une operation arithmetique sur 20 % du budget, pas un objectif hors d'atteinte.
A4: LA CANTINE (a saisir)
A5: Couverts par jour | B5: 300
A6: Jours ouvres par mois | B6: 20
A7: Cout matiere par repas (€) | B7: 2.5
A8: Budget alimentaire annuel HT (€) | B8: =B5*B6*B7*12
A9: Ratio durable actuel (%) | B9: 0.18 | C9: Issu du diagnostic, ou estime
A10: Ratio bio actuel (%) | B10: 0.07
A12: LES LEVIERS (part du budget x part basculee)
A13: Famille | B13: % budget | C13: % bascule | D13: Montant | E13: Gain durable | F13: Gain bio / commentaire
A14: Epicerie seche -> bio local | B14: 0.11 | C14: 1 | D14: =B8*B14*C14 | E14: =B14*C14 | F14: =B14*C14 | G14: PILOTE — zero froid, DLUO longue, souvent moins cher en direct
A15: Legumes bruts de saison -> bio local | B15: 0.1 | C15: 1 | D15: =B8*B15*C15 | E15: =B15*C15 | F15: =B15*C15 | G15: PILOTE — pas de chaine du froid, tolere 24 h de retard
A16: Oeufs -> bio | B16: 0.02 | C16: 1 | D16: =B8*B16*C16 | E16: =B16*C16 | F16: =B16*C16 | G16: Ajout semaine 3 — 28 j de DLC, temperature ambiante
A17: Produits laitiers -> bio | B17: 0.14 | C17: 0 | D17: =B8*B17*C17 | E17: =B17*C17 | F17: =B17*C17 | G17: Etage 4 — chaine du froid 0-4 °C stricte
A18: Viande -> Label Rouge | B18: 0.28 | C18: 0 | D18: =B8*B18*C18 | E18: =B18*C18 | F18: 0 | G18: Etage 4 mur — durable uniquement, pas bio. Surcout eleve
A19: Fruits de saison -> bio local | B19: 0.05 | C19: 0 | D19: =B8*B19*C19 | E19: =B19*C19 | F19: =B19*C19 | G19: Apres le pilote
A20: TOTAL BASCULE | D20: =SUM(D14:D19) | E20: =SUM(E14:E19) | F20: =SUM(F14:F19)
A22: RESULTAT
A23: Ratio DURABLE apres bascule | B23: =B9+E20 | C23: =IF(B23>=0.5,"SEUIL 50 % ATTEINT","il manque "&TEXT(0.5-B23,"0.0%"))
A24: Ratio BIO apres bascule | B24: =B10+F20 | C24: =IF(B24>=0.2,"SEUIL 20 % ATTEINT","il manque "&TEXT(0.2-B24,"0.0%"))
A26: MODE D'EMPLOI EN RENDEZ-VOUS : laisser les deux premieres lignes (epicerie seche + legumes bruts) a 100 % et tout le reste a 0 %. C'est le perimetre du pilote. Le seuil bio des 20 % est franchi avec DEUX familles, sans froid, sans camion, sans changer de grossiste principal. Puis montrer la suite du chemin en montant les laitiers a 50 % et la viande a 25 %.
A28: RAPPEL : le ratio se calcule en VALEUR d'achat, pas en volume. Le denominateur est la totalite des achats alimentaires, y compris ceux qu'on ne fournit pas — c'est pourquoi on ne garantit jamais la conformite : on la mesure et on la fait progresser (obligation de moyens).
